ERROR:    Exception in ASGI application
Traceback (most recent call last):
  File "/home/runner/workspace/.pythonlibs/lib/python3.11/site-packages/uvicorn/protocols/http/httptools_impl.py", line 409, in run_asgi
    result = await app(  # type: ignore[func-returns-value]
             ^^^^^^^^^^^^^^^^^^^^^^^^^^^^^^^^^^^^^^^^^^^^^^
  File "/home/runner/workspace/.pythonlibs/lib/python3.11/site-packages/uvicorn/middleware/proxy_headers.py", line 60, in __call__
    return await self.app(scope, receive, send)
           ^^^^^^^^^^^^^^^^^^^^^^^^^^^^^^^^^^^^
  File "/home/runner/workspace/.pythonlibs/lib/python3.11/site-packages/fastapi/applications.py", line 1054, in __call__
    await super().__call__(scope, receive, send)
  File "/home/runner/workspace/.pythonlibs/lib/python3.11/site-packages/starlette/applications.py", line 113, in __call__
    await self.middleware_stack(scope, receive, send)
  File "/home/runner/workspace/.pythonlibs/lib/python3.11/site-packages/starlette/middleware/errors.py", line 186, in __call__
    raise exc
  File "/home/runner/workspace/.pythonlibs/lib/python3.11/site-packages/starlette/middleware/errors.py", line 164, in __call__
    await self.app(scope, receive, _send)
  File "/home/runner/workspace/.pythonlibs/lib/python3.11/site-packages/starlette/middleware/cors.py", line 85, in __call__
    await self.app(scope, receive, send)
  File "/home/runner/workspace/.pythonlibs/lib/python3.11/site-packages/starlette/middleware/exceptions.py", line 63, in __call__
    await wrap_app_handling_exceptions(self.app, conn)(scope, receive, send)
  File "/home/runner/workspace/.pythonlibs/lib/python3.11/site-packages/starlette/_exception_handler.py", line 53, in wrapped_app
    raise exc
  File "/home/runner/workspace/.pythonlibs/lib/python3.11/site-packages/starlette/_exception_handler.py", line 42, in wrapped_app
    await app(scope, receive, sender)
  File "/home/runner/workspace/.pythonlibs/lib/python3.11/site-packages/starlette/routing.py", line 716, in __call__
    await self.middleware_stack(scope, receive, send)
  File "/home/runner/workspace/.pythonlibs/lib/python3.11/site-packages/starlette/routing.py", line 736, in app
    await route.handle(scope, receive, send)
  File "/home/runner/workspace/.pythonlibs/lib/python3.11/site-packages/starlette/routing.py", line 290, in handle
    await self.app(scope, receive, send)
  File "/home/runner/workspace/.pythonlibs/lib/python3.11/site-packages/starlette/routing.py", line 78, in app
    await wrap_app_handling_exceptions(app, request)(scope, receive, send)
  File "/home/runner/workspace/.pythonlibs/lib/python3.11/site-packages/starlette/_exception_handler.py", line 53, in wrapped_app
    raise exc
  File "/home/runner/workspace/.pythonlibs/lib/python3.11/site-packages/starlette/_exception_handler.py", line 42, in wrapped_app
    await app(scope, receive, sender)
  File "/home/runner/workspace/.pythonlibs/lib/python3.11/site-packages/starlette/routing.py", line 75, in app
    response = await f(request)
               ^^^^^^^^^^^^^^^^
  File "/home/runner/workspace/.pythonlibs/lib/python3.11/site-packages/fastapi/routing.py", line 302, in app
    raw_response = await run_endpoint_function(
                   ^^^^^^^^^^^^^^^^^^^^^^^^^^^^
  File "/home/runner/workspace/.pythonlibs/lib/python3.11/site-packages/fastapi/routing.py", line 213, in run_endpoint_function
    return await dependant.call(**values)
           ^^^^^^^^^^^^^^^^^^^^^^^^^^^^^^
  File "/home/runner/workspace/app/routers/public_idfs.py", line 107, in get_idfs
    if isinstance(idf_data["devices"], str):
                  ~~~~~~~~^^^^^^^^^^^
KeyError: 'devices'
INFO:     10.81.12.71:0 - "GET /api/trk/trinity/logo HTTP/1.1" 404 Not Found
INFO:     10.81.0.81:0 - "GET /api/trk/trinity/idfs?limit=50&include_health=1 HTTP/1.1" 500 Internal Server Error
ERROR:    Exception in ASGI application
Traceback (most recent call last):
  File "/home/runner/workspace/.pythonlibs/lib/python3.11/site-packages/uvicorn/protocols/http/httptools_impl.py", line 409, in run_asgi
    result = await app(  # type: ignore[func-returns-value]
             ^^^^^^^^^^^^^^^^^^^^^^^^^^^^^^^^^^^^^^^^^^^^^^
  File "/home/runner/workspace/.pythonlibs/lib/python3.11/site-packages/uvicorn/middleware/proxy_headers.py", line 60, in __call__
    return await self.app(scope, receive, send)
           ^^^^^^^^^^^^^^^^^^^^^^^^^^^^^^^^^^^^
  File "/home/runner/workspace/.pythonlibs/lib/python3.11/site-packages/fastapi/applications.py", line 1054, in __call__
    await super().__call__(scope, receive, send)
  File "/home/runner/workspace/.pythonlibs/lib/python3.11/site-packages/starlette/applications.py", line 113, in __call__
    await self.middleware_stack(scope, receive, send)
  File "/home/runner/workspace/.pythonlibs/lib/python3.11/site-packages/starlette/middleware/errors.py", line 186, in __call__
    raise exc
  File "/home/runner/workspace/.pythonlibs/lib/python3.11/site-packages/starlette/middleware/errors.py", line 164, in __call__
    await self.app(scope, receive, _send)
  File "/home/runner/workspace/.pythonlibs/lib/python3.11/site-packages/starlette/middleware/cors.py", line 85, in __call__
    await self.app(scope, receive, send)
  File "/home/runner/workspace/.pythonlibs/lib/python3.11/site-packages/starlette/middleware/exceptions.py", line 63, in __call__
    await wrap_app_handling_exceptions(self.app, conn)(scope, receive, send)
  File "/home/runner/workspace/.pythonlibs/lib/python3.11/site-packages/starlette/_exception_handler.py", line 53, in wrapped_app
    raise exc
  File "/home/runner/workspace/.pythonlibs/lib/python3.11/site-packages/starlette/_exception_handler.py", line 42, in wrapped_app
    await app(scope, receive, sender)
  File "/home/runner/workspace/.pythonlibs/lib/python3.11/site-packages/starlette/routing.py", line 716, in __call__
    await self.middleware_stack(scope, receive, send)
  File "/home/runner/workspace/.pythonlibs/lib/python3.11/site-packages/starlette/routing.py", line 736, in app
    await route.handle(scope, receive, send)
  File "/home/runner/workspace/.pythonlibs/lib/python3.11/site-packages/starlette/routing.py", line 290, in handle
    await self.app(scope, receive, send)
  File "/home/runner/workspace/.pythonlibs/lib/python3.11/site-packages/starlette/routing.py", line 78, in app
    await wrap_app_handling_exceptions(app, request)(scope, receive, send)
  File "/home/runner/workspace/.pythonlibs/lib/python3.11/site-packages/starlette/_exception_handler.py", line 53, in wrapped_app
    raise exc
  File "/home/runner/workspace/.pythonlibs/lib/python3.11/site-packages/starlette/_exception_handler.py", line 42, in wrapped_app
    await app(scope, receive, sender)
  File "/home/runner/workspace/.pythonlibs/lib/python3.11/site-packages/starlette/routing.py", line 75, in app
    response = await f(request)
               ^^^^^^^^^^^^^^^^
  File "/home/runner/workspace/.pythonlibs/lib/python3.11/site-packages/fastapi/routing.py", line 302, in app
    raw_response = await run_endpoint_function(
                   ^^^^^^^^^^^^^^^^^^^^^^^^^^^^
  File "/home/runner/workspace/.pythonlibs/lib/python3.11/site-packages/fastapi/routing.py", line 213, in run_endpoint_function
    return await dependant.call(**values)
           ^^^^^^^^^^^^^^^^^^^^^^^^^^^^^^
  File "/home/runner/workspace/app/routers/public_idfs.py", line 107, in get_idfs
    if isinstance(idf_data["devices"], str):
                  ~~~~~~~~^^^^^^^^^^^
KeyError: 'devices