ERROR:    Exception in ASGI application
Traceback (most recent call last):
  File "/home/runner/workspace/.pythonlibs/lib/python3.11/site-packages/starlette/responses.py", line 353, in __call__
    stat_result = await anyio.to_thread.run_sync(os.stat, self.path)
                  ^^^^^^^^^^^^^^^^^^^^^^^^^^^^^^^^^^^^^^^^^^^^^^^^^^
  File "/home/runner/workspace/.pythonlibs/lib/python3.11/site-packages/anyio/to_thread.py", line 56, in run_sync
    return await get_async_backend().run_sync_in_worker_thread(
           ^^^^^^^^^^^^^^^^^^^^^^^^^^^^^^^^^^^^^^^^^^^^^^^^^^^^
  File "/home/runner/workspace/.pythonlibs/lib/python3.11/site-packages/anyio/_backends/_asyncio.py", line 2476, in run_sync_in_worker_thread
    return await future
           ^^^^^^^^^^^^
  File "/home/runner/workspace/.pythonlibs/lib/python3.11/site-packages/anyio/_backends/_asyncio.py", line 967, in run
    result = context.run(func, *args)
             ^^^^^^^^^^^^^^^^^^^^^^^^
FileNotFoundError: [Errno 2] No such file or directory: 'dist/index.html'

During handling of the above exception, another exception occurred:

Traceback (most recent call last):
  File "/home/runner/workspace/.pythonlibs/lib/python3.11/site-packages/uvicorn/protocols/http/httptools_impl.py", line 409, in run_asgi
    result = await app(  # type: ignore[func-returns-value]
             ^^^^^^^^^^^^^^^^^^^^^^^^^^^^^^^^^^^^^^^^^^^^^^
  File "/home/runner/workspace/.pythonlibs/lib/python3.11/site-packages/uvicorn/middleware/proxy_headers.py", line 60, in __call__
    return await self.app(scope, receive, send)
           ^^^^^^^^^^^^^^^^^^^^^^^^^^^^^^^^^^^^
  File "/home/runner/workspace/.pythonlibs/lib/python3.11/site-packages/fastapi/applications.py", line 1054, in __call__
    await super().__call__(scope, receive, send)
  File "/home/runner/workspace/.pythonlibs/lib/python3.11/site-packages/starlette/applications.py", line 113, in __call__
    await self.middleware_stack(scope, receive, send)
  File "/home/runner/workspace/.pythonlibs/lib/python3.11/site-packages/starlette/middleware/errors.py", line 186, in __call__
    raise exc
  File "/home/runner/workspace/.pythonlibs/lib/python3.11/site-packages/starlette/middleware/errors.py", line 164, in __call__
    await self.app(scope, receive, _send)
  File "/home/runner/workspace/.pythonlibs/lib/python3.11/site-packages/starlette/middleware/cors.py", line 85, in __call__
    await self.app(scope, receive, send)
  File "/home/runner/workspace/.pythonlibs/lib/python3.11/site-packages/starlette/middleware/exceptions.py", line 63, in __call__
    await wrap_app_handling_exceptions(self.app, conn)(scope, receive, send)
  File "/home/runner/workspace/.pythonlibs/lib/python3.11/site-packages/starlette/_exception_handler.py", line 53, in wrapped_app
    raise exc
  File "/home/runner/workspace/.pythonlibs/lib/python3.11/site-packages/starlette/_exception_handler.py", line 42, in wrapped_app
    await app(scope, receive, sender)
  File "/home/runner/workspace/.pythonlibs/lib/python3.11/site-packages/starlette/routing.py", line 716, in __call__
    await self.middleware_stack(scope, receive, send)
  File "/home/runner/workspace/.pythonlibs/lib/python3.11/site-packages/starlette/routing.py", line 736, in app
    await route.handle(scope, receive, send)
  File "/home/runner/workspace/.pythonlibs/lib/python3.11/site-packages/starlette/routing.py", line 290, in handle
    await self.app(scope, receive, send)
  File "/home/runner/workspace/.pythonlibs/lib/python3.11/site-packages/starlette/routing.py", line 78, in app
    await wrap_app_handling_exceptions(app, request)(scope, receive, send)
  File "/home/runner/workspace/.pythonlibs/lib/python3.11/site-packages/starlette/_exception_handler.py", line 53, in wrapped_app
    raise exc
  File "/home/runner/workspace/.pythonlibs/lib/python3.11/site-packages/starlette/_exception_handler.py", line 42, in wrapped_app
    await app(scope, receive, sender)
  File "/home/runner/workspace/.pythonlibs/lib/python3.11/site-packages/starlette/routing.py", line 76, in app
    await response(scope, receive, send)
  File "/home/runner/workspace/.pythonlibs/lib/python3.11/site-packages/starlette/responses.py", line 356, in __call__
    raise RuntimeError(f"File at path {self.path} does not exist.")
RuntimeError: File at path dist/index.html does not exist.
